<?xml version="1.0" ?>
<!-- =================================================================================== -->
<!-- |    This document was autogenerated by xacro from xacro/primius.urdf.xacro       | -->
<!-- |    EDITING THIS FILE BY HAND IS NOT RECOMMENDED                                 | -->
<!-- =================================================================================== -->
<robot name="primius">
  <material name="blue">
    <color rgba="0 0 0.8 1"/>
  </material>
  <material name="white">
    <color rgba="1 1 1 1"/>
  </material>
  <link name="base_link">
    <visual>
      <geometry>
        <box size="0.35 0.25 0.1"/>
      </geometry>
      <material name="blue"/>
    </visual>
  </link>
  <link name="wheel_front_right">
    <visual>
      <geometry>
        <cylinder length="0.032" radius="0.068"/>
      </geometry>
      <material name="white"/>
    </visual>
  </link>
  <joint name="base_link_wheel_front_right" type="continuous">
    <parent link="base_link"/>
    <child link="wheel_front_right"/>
    <origin rpy="1.57 0.0 0.0" xyz="0.18 0.12 0.0"/>
  </joint>
</robot>
