<?xml version="1.0"?>
<robot name="primius">
    <material name="blue">
        <color rgba="0 0 0.8 1"/>
    </material>
    <material name="white">
        <color rgba="1 1 1 1"/>
    </material>
    <link name="base_link">
        <visual>
        <geometry>
                <box size="0.5 0.2 0.1"/>
        </geometry>
        <material name="blue"/>
        </visual>
    </link>
    <link name="wheel_front_right">
        <visual>
            <geometry>
                <cylinder radius="0.07" length="0.04"/>
            </geometry>
            <material name="white"/>
        </visual>
    </link>
    <joint name="base_link_wheel_front_right" type="continuous">
        <parent link="base_link"/>
        <child link="wheel_front_right"/>
        <origin xyz="0.18 0.12 0.0" rpy="1.57 0.0 0.0"/>
    </joint>
</robot>